<?xml version="1.0" ?>
<!-- =================================================================================== -->
<!-- |    This document was autogenerated by xacro from ./dexhand1.urdf.xacro          | -->
<!-- |    EDITING THIS FILE BY HAND IS NOT RECOMMENDED                                 | -->
<!-- =================================================================================== -->
<robot name="dexhand">
  <!-- create link fixed to the "world" -->
  <link name="world"/>
  <!-- define a joint connect to other part of robot -->
  <joint name="FOREARM" type="fixed">
    <origin rpy="0 0 0" xyz="0 0 0"/>
    <parent link="world"/>
    <child link="fabase"/>
  </joint>
  <!-- pure URDF goes below -->
  <link name="fabase">
    <inertial>
      <origin rpy="0 0 0" xyz="3.28758629066675E-07 -0.00280049370465237 0.0716119954420033"/>
      <mass value="0.116733232194003"/>
      <inertia ixx="0.000208688922136791" ixy="-1.09031140514313E-09" ixz="-2.33671160073293E-11" iyy="0.00019711724481563" iyz="-1.2662112896217E-06" izz="0.000114813277747077"/>
    </inertial>
    <visual>
      <origin rpy="0 0 0" xyz="0 0 0"/>
      <geometry>
        <mesh filename="meshes/fabase.STL"/>
      </geometry>
      <material name="">
        <color rgba="1 1 1 1"/>
      </material>
    </visual>
    <collision>
      <origin rpy="0 0 0" xyz="0 0 0"/>
      <geometry>
        <mesh filename="meshes/fabase.STL"/>
      </geometry>
    </collision>
  </link>
  <link name="falink2">
    <inertial>
      <origin rpy="0 0 0" xyz="8.10398166975479E-09 -4.01177173158664E-10 0.00549999656729894"/>
      <mass value="0.00127776584823899"/>
      <inertia ixx="5.01863386521225E-08" ixy="1.49370815701381E-14" ixz="5.14504997849144E-14" iyy="5.01863212003858E-08" iyz="-1.71620476408047E-14" izz="2.33715865191686E-08"/>
    </inertial>
    <visual>
      <origin rpy="0 0 0" xyz="0 0 0"/>
      <geometry>
        <mesh filename="meshes/falink2.STL"/>
      </geometry>
      <material name="">
        <color rgba="1 1 1 1"/>
      </material>
    </visual>
    <collision>
      <origin rpy="0 0 0" xyz="0 0 0"/>
      <geometry>
        <mesh filename="meshes/falink2.STL"/>
      </geometry>
    </collision>
  </link>
  <joint name="FAJ3" type="fixed">
    <origin rpy="0 0 1.5708" xyz="0 0.028001 0.1905"/>
    <parent link="fabase"/>
    <child link="falink2"/>
    <axis xyz="1 0 0"/>
    <limit acceleration="2.0" effort="0.1" lower="-0.5235" upper="0.5235" velocity="2.0"/>
  </joint>
  <link name="falink1">
    <inertial>
      <origin rpy="0 0 0" xyz="0.000716824630949655 -0.00609542828247423 0.0212910082526262"/>
      <mass value="0.00472896842585646"/>
      <inertia ixx="6.54620610890924E-07" ixy="-4.59836910833344E-09" ixz="-2.31746933177867E-09" iyy="6.07258952527567E-07" iyz="2.13128089899764E-07" izz="2.91836021108035E-07"/>
    </inertial>
    <visual>
      <origin rpy="0 0 0" xyz="0 0 0"/>
      <geometry>
        <mesh filename="meshes/falink1.STL"/>
      </geometry>
      <material name="">
        <color rgba="1 1 1 1"/>
      </material>
    </visual>
    <collision>
      <origin rpy="0 0 0" xyz="0 0 0"/>
      <geometry>
        <mesh filename="meshes/falink1.STL"/>
      </geometry>
    </collision>
  </link>
  <joint name="FAJ2" type="fixed">
    <origin rpy="0 0 -1.5708" xyz="0 0 0.011"/>
    <parent link="falink2"/>
    <child link="falink1"/>
  </joint>
  <link name="pmbase">
    <inertial>
      <origin rpy="0 0 0" xyz="8.53609692686815E-07 -0.024308776882631 0.00431490414497454"/>
      <mass value="0.00601940125483358"/>
      <inertia ixx="1.1544501152982E-06" ixy="3.47744097896483E-15" ixz="3.94374970071965E-14" iyy="1.62966970781033E-06" iyz="-3.95045587346745E-08" izz="2.68292417958557E-06"/>
    </inertial>
    <visual>
      <origin rpy="0 0 0" xyz="0 0 0"/>
      <geometry>
        <mesh filename="meshes/pmbase.STL"/>
      </geometry>
      <material name="">
        <color rgba="1 1 1 1"/>
      </material>
    </visual>
    <collision>
      <origin rpy="0 0 0" xyz="0 0 0"/>
      <geometry>
        <mesh filename="meshes/pmbase.STL"/>
      </geometry>
    </collision>
  </link>
  <joint name="FAJ1" type="fixed">
    <origin rpy="0 0 0" xyz="0 -0.0193 0.039"/>
    <parent link="falink1"/>
    <child link="pmbase"/>
    <axis xyz="-1 0 0"/>
    <limit acceleration="2.0" effort="0.1" lower="-0.2618" upper="0.5235" velocity="2.0"/>
  </joint>
  <!-- define a joint connect to other part of robot -->
  <joint name="PALM" type="fixed">
    <origin rpy="0 0 0" xyz="0 -0.0193 0.01"/>
    <parent link="pmbase"/>
    <child link="palm"/>
  </joint>
  <!-- pure URDF goes below -->
  <link name="palm">
    <inertial>
      <origin rpy="0 0 0" xyz="0.00467315921354322 -7.47612565492224E-06 0.0411612387388328"/>
      <mass value="0.0289828312541729"/>
      <inertia ixx="1.04474964158207E-05" ixy="1.02450222919575E-10" ixz="-1.80668551272074E-06" iyy="1.71178957503239E-05" iyz="2.35190736196329E-08" izz="8.47407472988603E-06"/>
    </inertial>
    <visual>
      <origin rpy="0 0 0" xyz="0 0 0"/>
      <geometry>
        <mesh filename="meshes/palm.STL"/>
      </geometry>
      <material name="">
        <color rgba="1 1 1 1"/>
      </material>
    </visual>
    <collision>
      <origin rpy="0 0 0" xyz="0 0 0"/>
      <geometry>
        <mesh filename="meshes/palm.STL"/>
      </geometry>
    </collision>
  </link>
  <link name="thbase">
    <inertial>
      <origin rpy="0 0 0" xyz="-0.00179428684346725 2.09600788479009E-08 0.00147248530806168"/>
      <mass value="0.00644352672209423"/>
      <inertia ixx="5.42712823895272E-07" ixy="4.57090657604939E-14" ixz="-2.41334457846003E-09" iyy="6.96430068620061E-07" iyz="2.45814092128719E-13" izz="8.14232088259366E-07"/>
    </inertial>
    <visual>
      <origin rpy="0 0 0" xyz="0 0 0"/>
      <geometry>
        <mesh filename="meshes/thbase.STL"/>
      </geometry>
      <material name="">
        <color rgba="1 1 1 1"/>
      </material>
    </visual>
    <collision>
      <origin rpy="0 0 0" xyz="0 0 0"/>
      <geometry>
        <mesh filename="meshes/thbase.STL"/>
      </geometry>
    </collision>
  </link>
  <joint name="THJ4" type="revolute">
    <origin rpy="3.14159 -1.5708 0" xyz="0.026851 0.01315 0.038"/>
    <parent link="palm"/>
    <child link="thbase"/>
    <axis xyz="1 0 0"/>
    <limit acceleration="2.0" effort="0.1" lower="-0.08" upper="1.5708" velocity="2.0"/>
  </joint>
  <link name="thproximal">
    <inertial>
      <origin rpy="0 0 0" xyz="0.00638369419270039 -8.78508188083445E-06 -0.000318318507908692"/>
      <mass value="0.00874436649921006"/>
      <inertia ixx="3.75939070373561E-07" ixy="-6.07919194575409E-09" ixz="7.50903074913542E-08" iyy="8.31777797638259E-07" iyz="-3.81373430695677E-09" izz="6.69794720992556E-07"/>
    </inertial>
    <visual>
      <origin rpy="0 0 0" xyz="0 0 0"/>
      <geometry>
        <mesh filename="meshes/thproximal.STL"/>
      </geometry>
      <material name="">
        <color rgba="1 1 1 1"/>
      </material>
    </visual>
    <collision>
      <origin rpy="0 0 0" xyz="0 0 0"/>
      <geometry>
        <mesh filename="meshes/thproximal.STL"/>
      </geometry>
    </collision>
  </link>
  <joint name="THJ3" type="revolute">
    <origin rpy="-1.5708 -1.5708 -1.5708" xyz="0 0 0.01575"/>
    <parent link="thbase"/>
    <child link="thproximal"/>
    <axis xyz="-1 0 0"/>
    <limit acceleration="2.0" effort="0.1" lower="0.0" upper="0.7854" velocity="2.0"/>
  </joint>
  <link name="thmiddle">
    <inertial>
      <origin rpy="0 0 0" xyz="-0.000696295114692514 0.000275414873780168 0.0255327021512566"/>
      <mass value="0.00591298052561849"/>
      <inertia ixx="1.06964496585371E-06" ixy="4.52496488925683E-09" ixz="-9.43881698085712E-09" iyy="8.9138484793407E-07" iyz="-2.36519713662575E-09" izz="2.4504036267044E-07"/>
    </inertial>
    <visual>
      <origin rpy="0 0 0" xyz="0 0 0"/>
      <geometry>
        <mesh filename="meshes/thmiddle.STL"/>
      </geometry>
      <material name="">
        <color rgba="1 1 1 1"/>
      </material>
    </visual>
    <collision>
      <origin rpy="0 0 0" xyz="0 0 0"/>
      <geometry>
        <mesh filename="meshes/thmiddle.STL"/>
      </geometry>
    </collision>
  </link>
  <joint name="THJ2" type="revolute">
    <origin rpy="1.5708 0 1.5708" xyz="0.025 0 0"/>
    <parent link="thproximal"/>
    <child link="thmiddle"/>
    <axis xyz="-1 0 0"/>
    <limit acceleration="2.0" effort="0.1" lower="0" upper="0.7854" velocity="2.0"/>
  </joint>
  <link name="thdistal">
    <inertial>
      <origin rpy="0 0 0" xyz="6.64428156433462E-05 -0.00522038889406494 0.0138629509312514"/>
      <mass value="0.0026081529494485"/>
      <inertia ixx="2.4445745986031E-07" ixy="-8.87971073806119E-10" ixz="2.3829151125442E-09" iyy="3.00016476075754E-07" iyz="2.34308014393757E-08" izz="1.03721856739173E-07"/>
    </inertial>
    <visual>
      <origin rpy="0 0 0" xyz="0 0 0"/>
      <geometry>
        <mesh filename="meshes/thdistal.STL"/>
      </geometry>
      <material name="">
        <color rgba="1 1 1 1"/>
      </material>
    </visual>
    <collision>
      <origin rpy="0 0 0" xyz="0 0 0"/>
      <geometry>
        <mesh filename="meshes/thdistal.STL"/>
      </geometry>
    </collision>
  </link>
  <joint name="THJ1" type="revolute">
    <origin rpy="0 0 0" xyz="0 0.003 0.045"/>
    <parent link="thmiddle"/>
    <child link="thdistal"/>
    <axis xyz="-1 0 0"/>
    <limit acceleration="2.0" effort="0.1" lower="0.0" upper="1.5708" velocity="2.0"/>
  </joint>
  <link name="thtip">
  </link>
  <joint name="THJ0" type="fixed">
    <origin rpy="0 0 0" xyz="0 -0.0015 0.0297"/>
    <parent link="thdistal"/>
    <child link="thtip"/>
    <axis xyz="0 0 0"/>
  </joint>
  <link name="ffbase">
    <inertial>
      <origin rpy="0 0 0" xyz="-0.00112189286961021 0.000208475541508962 0.00617879877072101"/>
      <mass value="0.00757937353888617"/>
      <inertia ixx="4.40333843672738E-07" ixy="-1.02490543565402E-09" ixz="4.38718638849792E-08" iyy="5.89927525754156E-07" iyz="-3.16407618692666E-09" izz="3.37649595953186E-07"/>
    </inertial>
    <visual>
      <origin rpy="0 0 0" xyz="0 0 0"/>
      <geometry>
        <mesh filename="meshes/ffbase.STL"/>
      </geometry>
      <material name="">
        <color rgba="1 1 1 1"/>
      </material>
    </visual>
    <collision>
      <origin rpy="0 0 0" xyz="0 0 0"/>
      <geometry>
        <mesh filename="meshes/ffbase.STL"/>
      </geometry>
    </collision>
  </link>
  <joint name="FFJ4" type="revolute">
    <origin rpy="0 0 1.5708" xyz="0.030504 0.00045 0.0855"/>
    <parent link="palm"/>
    <child link="ffbase"/>
    <axis xyz="1 0 0"/>
    <limit acceleration="2.0" effort="0.1" lower="-0.1309" upper="0.1309" velocity="2.0"/>
  </joint>
  <link name="ffproximal">
    <inertial>
      <origin rpy="0 0 0" xyz="-0.00196718827387735 -0.000248547242294944 0.0263051638016935"/>
      <mass value="0.00551109036052712"/>
      <inertia ixx="1.03795704448418E-06" ixy="9.78527304732066E-09" ixz="-1.65538602717097E-08" iyy="8.70275327312006E-07" iyz="2.11379894396707E-08" izz="2.37607854319465E-07"/>
    </inertial>
    <visual>
      <origin rpy="0 0 0" xyz="0 0 0"/>
      <geometry>
        <mesh filename="meshes/ffproximal.STL"/>
      </geometry>
      <material name="">
        <color rgba="1 1 1 1"/>
      </material>
    </visual>
    <collision>
      <origin rpy="0 0 0" xyz="0 0 0"/>
      <geometry>
        <mesh filename="meshes/ffproximal.STL"/>
      </geometry>
    </collision>
  </link>
  <joint name="FFJ3" type="revolute">
    <origin rpy="0 0 -1.5708" xyz="0 0 0.018"/>
    <parent link="ffbase"/>
    <child link="ffproximal"/>
    <axis xyz="-1 0 0"/>
    <limit acceleration="2.0" effort="0.1" lower="0.0" upper="1.5708" velocity="2.0"/>
  </joint>
  <link name="ffmiddle">
    <inertial>
      <origin rpy="0 0 0" xyz="0.000382629545805049 -0.00305057294683708 0.0123468373884281"/>
      <mass value="0.00397399477571205"/>
      <inertia ixx="3.35444191564615E-07" ixy="1.38344669695991E-09" ixz="4.95002685384417E-10" iyy="2.47384897956612E-07" iyz="-2.70391779997592E-09" izz="1.30213703964171E-07"/>
    </inertial>
    <visual>
      <origin rpy="0 0 0" xyz="0 0 0"/>
      <geometry>
        <mesh filename="meshes/ffmiddle.STL"/>
      </geometry>
      <material name="">
        <color rgba="1 1 1 1"/>
      </material>
    </visual>
    <collision>
      <origin rpy="0 0 0" xyz="0 0 0"/>
      <geometry>
        <mesh filename="meshes/ffmiddle.STL"/>
      </geometry>
    </collision>
  </link>
  <joint name="FFJ2" type="revolute">
    <origin rpy="0 0 0" xyz="0 0.003 0.045"/>
    <parent link="ffproximal"/>
    <child link="ffmiddle"/>
    <axis xyz="-1 0 0"/>
    <limit acceleration="2.0" effort="0.1" lower="0.0" upper="1.5708" velocity="2.0"/>
  </joint>
  <link name="ffdistal">
    <inertial>
      <origin rpy="0 0 0" xyz="0.00010613110729394 -0.00174210782128108 0.0146517272199787"/>
      <mass value="0.00588197848950502"/>
      <inertia ixx="4.26396352053566E-07" ixy="4.26289208202645E-10" ixz="-4.45633109841644E-09" iyy="4.68862862225653E-07" iyz="3.43678418970898E-08" izz="1.5593360356169E-07"/>
    </inertial>
    <visual>
      <origin rpy="0 0 0" xyz="0 0 0"/>
      <geometry>
        <mesh filename="meshes/ffdistal.STL"/>
      </geometry>
      <material name="">
        <color rgba="1 1 1 1"/>
      </material>
    </visual>
    <collision>
      <origin rpy="0 0 0" xyz="0 0 0"/>
      <geometry>
        <mesh filename="meshes/ffdistal.STL"/>
      </geometry>
    </collision>
  </link>
  <joint name="FFJ1" type="revolute">
    <origin rpy="0 0 0" xyz="0 0 0.025"/>
    <parent link="ffmiddle"/>
    <child link="ffdistal"/>
    <axis xyz="-1 0 0"/>
    <limit acceleration="2.0" effort="0.1" lower="0.0" upper="1.5708" velocity="2.0"/>
  </joint>
  <link name="fftip">
  </link>
  <joint name="FFJ0" type="fixed">
    <origin rpy="0 0 0" xyz="0 -0.0023033 0.03281"/>
    <parent link="ffdistal"/>
    <child link="fftip"/>
    <axis xyz="0 0 0"/>
  </joint>
  <link name="mfbase">
    <inertial>
      <origin rpy="0 0 0" xyz="-0.00112189286961018 0.000208475541508975 0.00617879877072106"/>
      <mass value="0.00757937353888616"/>
      <inertia ixx="4.40333843672737E-07" ixy="-1.02490543565387E-09" ixz="4.38718638849789E-08" iyy="5.89927525754155E-07" iyz="-3.16407618692692E-09" izz="3.37649595953185E-07"/>
    </inertial>
    <visual>
      <origin rpy="0 0 0" xyz="0 0 0"/>
      <geometry>
        <mesh filename="meshes/mfbase.STL"/>
      </geometry>
      <material name="">
        <color rgba="1 1 1 1"/>
      </material>
    </visual>
    <collision>
      <origin rpy="0 0 0" xyz="0 0 0"/>
      <geometry>
        <mesh filename="meshes/mfbase.STL"/>
      </geometry>
    </collision>
  </link>
  <joint name="MFJ4" type="revolute">
    <origin rpy="0 0 1.5708" xyz="0.0075044 0.00045 0.0905"/>
    <parent link="palm"/>
    <child link="mfbase"/>
    <axis xyz="1 0 0"/>
    <limit acceleration="2.0" effort="0.1" lower="-0.2616" upper="0.2616" velocity="2.0"/>
  </joint>
  <link name="mfproximal">
    <inertial>
      <origin rpy="0 0 0" xyz="-0.00196718827387734 -0.000248547242294942 0.0263051638016935"/>
      <mass value="0.00551109036052712"/>
      <inertia ixx="1.03795704448418E-06" ixy="9.78527304732057E-09" ixz="-1.65538602717095E-08" iyy="8.70275327312005E-07" iyz="2.11379894396709E-08" izz="2.37607854319465E-07"/>
    </inertial>
    <visual>
      <origin rpy="0 0 0" xyz="0 0 0"/>
      <geometry>
        <mesh filename="meshes/mfproximal.STL"/>
      </geometry>
      <material name="">
        <color rgba="1 1 1 1"/>
      </material>
    </visual>
    <collision>
      <origin rpy="0 0 0" xyz="0 0 0"/>
      <geometry>
        <mesh filename="meshes/mfproximal.STL"/>
      </geometry>
    </collision>
  </link>
  <joint name="MFJ3" type="revolute">
    <origin rpy="0 0 -1.5708" xyz="0 0 0.018"/>
    <parent link="mfbase"/>
    <child link="mfproximal"/>
    <axis xyz="-1 0 0"/>
    <limit acceleration="2.0" effort="0.1" lower="0.0" upper="1.5708" velocity="2.0"/>
  </joint>
  <link name="mfmiddle">
    <inertial>
      <origin rpy="0 0 0" xyz="0.000382629545805061 -0.00305057294683722 0.0123468373884282"/>
      <mass value="0.00397399477571206"/>
      <inertia ixx="3.35444191564803E-07" ixy="1.38344669695981E-09" ixz="4.95002685384687E-10" iyy="2.47384897956613E-07" iyz="-2.703917799971E-09" izz="1.30213703964359E-07"/>
    </inertial>
    <visual>
      <origin rpy="0 0 0" xyz="0 0 0"/>
      <geometry>
        <mesh filename="meshes/mfmiddle.STL"/>
      </geometry>
      <material name="">
        <color rgba="1 1 1 1"/>
      </material>
    </visual>
    <collision>
      <origin rpy="0 0 0" xyz="0 0 0"/>
      <geometry>
        <mesh filename="meshes/mfmiddle.STL"/>
      </geometry>
    </collision>
  </link>
  <joint name="MFJ2" type="revolute">
    <origin rpy="0 0 0" xyz="0 0.003 0.045"/>
    <parent link="mfproximal"/>
    <child link="mfmiddle"/>
    <axis xyz="-1 0 0"/>
    <limit acceleration="2.0" effort="0.1" lower="0.0" upper="1.5708" velocity="2.0"/>
  </joint>
  <link name="mfdistal">
    <inertial>
      <origin rpy="0 0 0" xyz="0.000106134004411035 -0.00174210903101383 0.0146517228171518"/>
      <mass value="0.00588198032947831"/>
      <inertia ixx="4.2639635533418E-07" ixy="4.26298827754549E-10" ixz="-4.45631713308347E-09" iyy="4.68862859926092E-07" iyz="3.43678259360068E-08" izz="1.55933618695065E-07"/>
    </inertial>
    <visual>
      <origin rpy="0 0 0" xyz="0 0 0"/>
      <geometry>
        <mesh filename="meshes/mfdistal.STL"/>
      </geometry>
      <material name="">
        <color rgba="1 1 1 1"/>
      </material>
    </visual>
    <collision>
      <origin rpy="0 0 0" xyz="0 0 0"/>
      <geometry>
        <mesh filename="meshes/mfdistal.STL"/>
      </geometry>
    </collision>
  </link>
  <joint name="MFJ1" type="revolute">
    <origin rpy="0 0 0" xyz="0 0 0.025"/>
    <parent link="mfmiddle"/>
    <child link="mfdistal"/>
    <axis xyz="-1 0 0"/>
    <limit acceleration="2.0" effort="0.1" lower="0.0" upper="1.5708" velocity="2.0"/>
  </joint>
  <link name="mftip">
  </link>
  <joint name="MFJ0" type="fixed">
    <origin rpy="0 0 0" xyz="0 -0.0023033 0.03281"/>
    <parent link="mfdistal"/>
    <child link="mftip"/>
    <axis xyz="0 0 0"/>
  </joint>
  <link name="rfbase">
    <inertial>
      <origin rpy="0 0 0" xyz="-0.00112189286961019 0.000208475541508962 0.00617879877072104"/>
      <mass value="0.00757937353888616"/>
      <inertia ixx="4.40333843672737E-07" ixy="-1.02490543565392E-09" ixz="4.38718638849791E-08" iyy="5.89927525754155E-07" iyz="-3.16407618692704E-09" izz="3.37649595953185E-07"/>
    </inertial>
    <visual>
      <origin rpy="0 0 0" xyz="0 0 0"/>
      <geometry>
        <mesh filename="meshes/rfbase.STL"/>
      </geometry>
      <material name="">
        <color rgba="1 1 1 1"/>
      </material>
    </visual>
    <collision>
      <origin rpy="0 0 0" xyz="0 0 0"/>
      <geometry>
        <mesh filename="meshes/rfbase.STL"/>
      </geometry>
    </collision>
  </link>
  <joint name="RFJ4" type="revolute">
    <origin rpy="0 0 1.5708" xyz="-0.015496 0.00045 0.0855"/>
    <parent link="palm"/>
    <child link="rfbase"/>
    <axis xyz="1 0 0"/>
    <limit acceleration="2.0" effort="0.1" lower="-0.2616" upper="0.2616" velocity="2.0"/>
  </joint>
  <link name="rfproximal">
    <inertial>
      <origin rpy="0 0 0" xyz="-0.00196718827387735 -0.000248547242294945 0.0263051638016935"/>
      <mass value="0.00551109036052711"/>
      <inertia ixx="1.03795704448418E-06" ixy="9.78527304732063E-09" ixz="-1.65538602717104E-08" iyy="8.70275327312006E-07" iyz="2.11379894396705E-08" izz="2.37607854319463E-07"/>
    </inertial>
    <visual>
      <origin rpy="0 0 0" xyz="0 0 0"/>
      <geometry>
        <mesh filename="meshes/rfproximal.STL"/>
      </geometry>
      <material name="">
        <color rgba="1 1 1 1"/>
      </material>
    </visual>
    <collision>
      <origin rpy="0 0 0" xyz="0 0 0"/>
      <geometry>
        <mesh filename="meshes/rfproximal.STL"/>
      </geometry>
    </collision>
  </link>
  <joint name="RFJ3" type="revolute">
    <origin rpy="0 0 -1.5708" xyz="0 0 0.018"/>
    <parent link="rfbase"/>
    <child link="rfproximal"/>
    <axis xyz="-1 0 0"/>
    <limit acceleration="2.0" effort="0.1" lower="0.0" upper="1.5708" velocity="2.0"/>
  </joint>
  <link name="rfmiddle">
    <inertial>
      <origin rpy="0 0 0" xyz="0.000382629545805044 -0.00305057294683722 0.0123468373884282"/>
      <mass value="0.00397399477571206"/>
      <inertia ixx="3.3544419156483E-07" ixy="1.38344669695899E-09" ixz="4.95002685384575E-10" iyy="2.47384897956613E-07" iyz="-2.7039177999714E-09" izz="1.30213703964385E-07"/>
    </inertial>
    <visual>
      <origin rpy="0 0 0" xyz="0 0 0"/>
      <geometry>
        <mesh filename="meshes/rfmiddle.STL"/>
      </geometry>
      <material name="">
        <color rgba="1 1 1 1"/>
      </material>
    </visual>
    <collision>
      <origin rpy="0 0 0" xyz="0 0 0"/>
      <geometry>
        <mesh filename="meshes/rfmiddle.STL"/>
      </geometry>
    </collision>
  </link>
  <joint name="RFJ2" type="revolute">
    <origin rpy="0 0 0" xyz="0 0.003 0.045"/>
    <parent link="rfproximal"/>
    <child link="rfmiddle"/>
    <axis xyz="-1 0 0"/>
    <limit acceleration="2.0" effort="0.1" lower="0.0" upper="1.5708" velocity="2.0"/>
  </joint>
  <link name="rfdistal">
    <inertial>
      <origin rpy="0 0 0" xyz="0.000105533826227052 -0.00174245491421043 0.0146518770270997"/>
      <mass value="0.00588145131515303"/>
      <inertia ixx="4.26346619813091E-07" ixy="4.55156716114043E-10" ixz="-4.46484447447954E-09" iyy="4.68820009905352E-07" iyz="3.43579383267477E-08" izz="1.55875343716759E-07"/>
    </inertial>
    <visual>
      <origin rpy="0 0 0" xyz="0 0 0"/>
      <geometry>
        <mesh filename="meshes/rfdistal.STL"/>
      </geometry>
      <material name="">
        <color rgba="1 1 1 1"/>
      </material>
    </visual>
    <collision>
      <origin rpy="0 0 0" xyz="0 0 0"/>
      <geometry>
        <mesh filename="meshes/rfdistal.STL"/>
      </geometry>
    </collision>
  </link>
  <joint name="RFJ1" type="revolute">
    <origin rpy="0 0 0" xyz="0 0 0.025"/>
    <parent link="rfmiddle"/>
    <child link="rfdistal"/>
    <axis xyz="-1 0 0"/>
    <limit acceleration="2.0" effort="0.1" lower="0.0" upper="1.5708" velocity="2.0"/>
  </joint>
  <link name="rftip">
  </link>
  <joint name="RFJ0" type="fixed">
    <origin rpy="0 0 0" xyz="0 -0.0023033 0.03281"/>
    <parent link="rfdistal"/>
    <child link="rftip"/>
    <axis xyz="0 0 0"/>
  </joint>
  <link name="lfpalm">
    <inertial>
      <origin rpy="0 0 0" xyz="0.00952070102948792 -0.000716360636126134 0.0177911371602309"/>
      <mass value="0.00678369782170271"/>
      <inertia ixx="4.10675769110166E-07" ixy="3.05378125911323E-08" ixz="-1.43648699262145E-07" iyy="6.84885914107377E-07" iyz="1.21865059132884E-08" izz="5.84455425338444E-07"/>
    </inertial>
    <visual>
      <origin rpy="0 0 0" xyz="0 0 0"/>
      <geometry>
        <mesh filename="meshes/lfpalm.STL"/>
      </geometry>
      <material name="">
        <color rgba="1 1 1 1"/>
      </material>
    </visual>
    <collision>
      <origin rpy="0 0 0" xyz="0 0 0"/>
      <geometry>
        <mesh filename="meshes/lfpalm.STL"/>
      </geometry>
    </collision>
  </link>
  <joint name="LFJ5" type="fixed">
    <origin rpy="0 -1.0472 0" xyz="-0.025779 0 0.032848"/>
    <parent link="palm"/>
    <child link="lfpalm"/>
    <axis xyz="-1 0 0"/>
    <limit acceleration="2.0" effort="0.1" lower="0.0" upper="1.5708" velocity="2.0"/>
  </joint>
  <link name="lfbase">
    <inertial>
      <origin rpy="0 0 0" xyz="-0.00112189286961001 0.000208475541513729 0.0061787987707209"/>
      <mass value="0.00757937353888615"/>
      <inertia ixx="4.40333843672739E-07" ixy="-1.02490543562026E-09" ixz="4.38718638849765E-08" iyy="5.89927525754149E-07" iyz="-3.16407618712094E-09" izz="3.37649595953187E-07"/>
    </inertial>
    <visual>
      <origin rpy="0 0 0" xyz="0 0 0"/>
      <geometry>
        <mesh filename="meshes/lfbase.STL"/>
      </geometry>
      <material name="">
        <color rgba="1 1 1 1"/>
      </material>
    </visual>
    <collision>
      <origin rpy="0 0 0" xyz="0 0 0"/>
      <geometry>
        <mesh filename="meshes/lfbase.STL"/>
      </geometry>
    </collision>
  </link>
  <joint name="LFJ4" type="revolute">
    <origin rpy="1.0472 0 1.5708" xyz="0.034911 0.00045 0.034839"/>
    <parent link="lfpalm"/>
    <child link="lfbase"/>
    <axis xyz="1 0 0"/>
    <limit acceleration="2.0" effort="0.1" lower="-0.2616" upper="0.2616" velocity="2.0"/>
  </joint>
  <link name="lfproximal">
    <inertial>
      <origin rpy="0 0 0" xyz="-0.00196718827389752 -0.000248547242294942 0.026305163801692"/>
      <mass value="0.00551109036052711"/>
      <inertia ixx="1.0379570444842E-06" ixy="9.78527304730434E-09" ixz="-1.65538602710957E-08" iyy="8.70275327312005E-07" iyz="2.11379894396788E-08" izz="2.37607854319437E-07"/>
    </inertial>
    <visual>
      <origin rpy="0 0 0" xyz="0 0 0"/>
      <geometry>
        <mesh filename="meshes/lfproximal.STL"/>
      </geometry>
      <material name="">
        <color rgba="1 1 1 1"/>
      </material>
    </visual>
    <collision>
      <origin rpy="0 0 0" xyz="0 0 0"/>
      <geometry>
        <mesh filename="meshes/lfproximal.STL"/>
      </geometry>
    </collision>
  </link>
  <joint name="LFJ3" type="revolute">
    <origin rpy="0 0 -1.5708" xyz="0 0 0.018"/>
    <parent link="lfbase"/>
    <child link="lfproximal"/>
    <axis xyz="-1 0 0"/>
    <limit acceleration="2.0" effort="0.1" lower="0.0" upper="1.5708" velocity="2.0"/>
  </joint>
  <link name="lfmiddle">
    <inertial>
      <origin rpy="0 0 0" xyz="0.000382629545795585 -0.00305057294683723 0.0123468373884285"/>
      <mass value="0.00397399477571205"/>
      <inertia ixx="3.35444191564547E-07" ixy="1.38344669696349E-09" ixz="4.95002685542594E-10" iyy="2.47384897956285E-07" iyz="-2.70391779997448E-09" izz="1.30213703964431E-07"/>
    </inertial>
    <visual>
      <origin rpy="0 0 0" xyz="0 0 0"/>
      <geometry>
        <mesh filename="meshes/lfmiddle.STL"/>
      </geometry>
      <material name="">
        <color rgba="1 1 1 1"/>
      </material>
    </visual>
    <collision>
      <origin rpy="0 0 0" xyz="0 0 0"/>
      <geometry>
        <mesh filename="meshes/lfmiddle.STL"/>
      </geometry>
    </collision>
  </link>
  <joint name="LFJ2" type="revolute">
    <origin rpy="0 0 0" xyz="0 0.003 0.045"/>
    <parent link="lfproximal"/>
    <child link="lfmiddle"/>
    <axis xyz="-1 0 0"/>
    <limit acceleration="2.0" effort="0.1" lower="0.0" upper="1.5708" velocity="2.0"/>
  </joint>
  <link name="lfdistal">
    <inertial>
      <origin rpy="0 0 0" xyz="0.000105517467005448 -0.00174246287824984 0.0146518725605457"/>
      <mass value="0.00588144497831721"/>
      <inertia ixx="4.26347396534589E-07" ixy="4.55104706366137E-10" ixz="-4.4640805732829E-09" iyy="4.68819653775823E-07" iyz="3.43585680004646E-08" izz="1.55874900663911E-07"/>
    </inertial>
    <visual>
      <origin rpy="0 0 0" xyz="0 0 0"/>
      <geometry>
        <mesh filename="meshes/lfdistal.STL"/>
      </geometry>
      <material name="">
        <color rgba="1 1 1 1"/>
      </material>
    </visual>
    <collision>
      <origin rpy="0 0 0" xyz="0 0 0"/>
      <geometry>
        <mesh filename="meshes/lfdistal.STL"/>
      </geometry>
    </collision>
  </link>
  <joint name="LFJ1" type="revolute">
    <origin rpy="0 0 0" xyz="0 0 0.025"/>
    <parent link="lfmiddle"/>
    <child link="lfdistal"/>
    <axis xyz="-1 0 0"/>
    <limit acceleration="2.0" effort="0.1" lower="0.0" upper="1.5708" velocity="2.0"/>
  </joint>
  <link name="lftip">
  </link>
  <joint name="LFJ0" type="fixed">
    <origin rpy="0 0 0" xyz="0 -0.0023033 0.03281"/>
    <parent link="lfdistal"/>
    <child link="lftip"/>
    <axis xyz="0 0 0"/>
  </joint>
  <link name="central">
  </link>
  <joint name="CJ0" type="fixed">
    <origin rpy="0 0 0" xyz="0 0.01265 0.045"/>
    <parent link="palm"/>
    <child link="central"/>
    <axis xyz="0 0 0"/>
  </joint>
  <!-- construct pure URDF end -->
</robot>
